<sdf version='1.7'>
  <model name='example_track_simple_wheels'>
    <link name='base_link'>
      <inertial>
        <pose>-0.057143 0 0 0 -0 0</pose>
        <mass>1.4</mass>
        <inertia>
          <ixx>0.0140694</ixx>
          <ixy>2.35427e-19</ixy>
          <ixz>0</ixz>
          <iyy>0.0339144</iyy>
          <iyz>0</iyz>
          <izz>0.045498</izz>
        </inertia>
      </inertial>
      <collision name='base_link_collision'>
        <pose>0 0 0 0 -0 0</pose>
        <geometry>
          <box>
            <size>0.1 0.1 0.1</size>
          </box>
        </geometry>
      </collision>
      <collision name='base_link_fixed_joint_lump__idler_left_collision_1'>
        <pose>-0.2 0.095 0 1.5708 -0 0</pose>
        <geometry>
          <cylinder>
            <length>0.1115</length>
            <radius>0.064</radius>
          </cylinder>
        </geometry>
      </collision>
      <collision name='base_link_fixed_joint_lump__idler_right_collision_2'>
        <pose>-0.2 -0.095 0 1.5708 -0 0</pose>
        <geometry>
          <cylinder>
            <length>0.1115</length>
            <radius>0.064</radius>
          </cylinder>
        </geometry>
      </collision>
      <visual name='base_link_visual'>
        <pose>0 0 0 0 -0 0</pose>
        <geometry>
          <box>
            <size>0.1 0.1 0.1</size>
          </box>
        </geometry>
      </visual>
      <visual name='base_link_fixed_joint_lump__idler_left_visual_1'>
        <pose>-0.2 0.095 0 1.5708 -0 0</pose>
        <geometry>
          <cylinder>
            <length>0.1115</length>
            <radius>0.064</radius>
          </cylinder>
        </geometry>
      </visual>
      <visual name='base_link_fixed_joint_lump__idler_right_visual_2'>
        <pose>-0.2 -0.095 0 1.5708 -0 0</pose>
        <geometry>
          <cylinder>
            <length>0.1115</length>
            <radius>0.064</radius>
          </cylinder>
        </geometry>
      </visual>
    </link>
    <joint name='sprocket_left_axle' type='revolute'>
      <pose relative_to='base_link'>0.2 0.095 0 0 -0 0</pose>
      <parent>base_link</parent>
      <child>sprocket_left</child>
      <axis>
        <xyz>0 1 0</xyz>
        <limit>
          <lower>-1e+16</lower>
          <upper>1e+16</upper>
        </limit>
        <dynamics>
          <spring_reference>0</spring_reference>
          <spring_stiffness>0</spring_stiffness>
        </dynamics>
      </axis>
    </joint>
    <link name='sprocket_left'>
      <pose relative_to='sprocket_left_axle'>0 0 0 0 -0 0</pose>
      <inertial>
        <pose>0 0 0 0 -0 0</pose>
        <mass>0.2</mass>
        <inertia>
          <ixx>0.000412004</ixx>
          <ixy>0</ixy>
          <ixz>0</ixz>
          <iyy>0.0004096</iyy>
          <iyz>0</iyz>
          <izz>0.000412004</izz>
        </inertia>
      </inertial>
      <collision name='sprocket_left_collision'>
        <pose>0 0 0 1.5708 -0 0</pose>
        <geometry>
          <cylinder>
            <length>0.1115</length>
            <radius>0.064</radius>
          </cylinder>
        </geometry>
      </collision>
      <visual name='sprocket_left_visual'>
        <pose>0 0 0 1.5708 -0 0</pose>
        <geometry>
          <cylinder>
            <length>0.1115</length>
            <radius>0.064</radius>
          </cylinder>
        </geometry>
      </visual>
      <visual name='sprocket_left_visual_1'>
        <pose>0 0 0 0 -0 0</pose>
        <geometry>
          <box>
            <size>0.01 0.1115 0.1</size>
          </box>
        </geometry>
      </visual>
      <visual name='sprocket_left_visual_2'>
        <pose>0 0 0 0 -0 0</pose>
        <geometry>
          <box>
            <size>0.1 0.1115 0.01</size>
          </box>
        </geometry>
      </visual>
    </link>
    <joint name='sprocket_right_axle' type='revolute'>
      <pose relative_to='base_link'>0.2 -0.095 0 0 -0 0</pose>
      <parent>base_link</parent>
      <child>sprocket_right</child>
      <axis>
        <xyz>0 1 0</xyz>
        <limit>
          <lower>-1e+16</lower>
          <upper>1e+16</upper>
        </limit>
        <dynamics>
          <spring_reference>0</spring_reference>
          <spring_stiffness>0</spring_stiffness>
        </dynamics>
      </axis>
    </joint>
    <link name='sprocket_right'>
      <pose relative_to='sprocket_right_axle'>0 0 0 0 -0 0</pose>
      <inertial>
        <pose>0 0 0 0 -0 0</pose>
        <mass>0.2</mass>
        <inertia>
          <ixx>0.000412004</ixx>
          <ixy>0</ixy>
          <ixz>0</ixz>
          <iyy>0.0004096</iyy>
          <iyz>0</iyz>
          <izz>0.000412004</izz>
        </inertia>
      </inertial>
      <collision name='sprocket_right_collision'>
        <pose>0 0 0 1.5708 -0 0</pose>
        <geometry>
          <cylinder>
            <length>0.1115</length>
            <radius>0.064</radius>
          </cylinder>
        </geometry>
      </collision>
      <visual name='sprocket_right_visual'>
        <pose>0 0 0 1.5708 -0 0</pose>
        <geometry>
          <cylinder>
            <length>0.1115</length>
            <radius>0.064</radius>
          </cylinder>
        </geometry>
      </visual>
      <visual name='sprocket_right_visual_1'>
        <pose>0 0 0 0 -0 0</pose>
        <geometry>
          <box>
            <size>0.01 0.1115 0.1</size>
          </box>
        </geometry>
      </visual>
      <visual name='sprocket_right_visual_2'>
        <pose>0 0 0 0 -0 0</pose>
        <geometry>
          <box>
            <size>0.1 0.1115 0.01</size>
          </box>
        </geometry>
      </visual>
    </link>
    <link name='track_wheel_link0'>
      <pose>0.35 0 0.125 0 -0 0</pose>
      <inertial>
        <pose>0 0 -0.125 1.5708 -0 0</pose>
        <mass>0.0571429</mass>
        <inertia>
          <ixx>0.00141369</ixx>
          <ixy>0</ixy>
          <ixz>0</ixz>
          <iyy>0.00141369</iyy>
          <iyz>0</iyz>
          <izz>0.000446429</izz>
        </inertia>
      </inertial>
      <collision name='collision'>
        <pose>0 0 -0.125 1.5708 -0 0</pose>
        <geometry>
          <cylinder>
            <length>0.5</length>
            <radius>0.125</radius>
          </cylinder>
        </geometry>
        <surface>
          <friction>
            <ode>
              <mu>0.5</mu>
              <mu2>0.5</mu2>
            </ode>
          </friction>
          <contact>
            <ode>
              <min_depth>0.01</min_depth>
            </ode>
          </contact>
        </surface>
      </collision>
      <visual name='visual'>
        <pose>0 0 -0.125 1.5708 -0 0</pose>
        <geometry>
          <cylinder>
            <length>0.5</length>
            <radius>0.125</radius>
          </cylinder>
        </geometry>
        <material>
          <ambient>0.3 0.1 0.1 1</ambient>
          <diffuse>0.2 0.2 0.2 1</diffuse>
          <specular>0 0 0 1</specular>
          <emissive>0 0 0 1</emissive>
        </material>
      </visual>
    </link>
    <link name='track_wheel_link1'>
      <pose>0.233333 0 0.125 0 -0 0</pose>
      <inertial>
        <pose>0 0 -0.125 1.5708 -0 0</pose>
        <mass>0.0571429</mass>
        <inertia>
          <ixx>0.00141369</ixx>
          <ixy>0</ixy>
          <ixz>0</ixz>
          <iyy>0.00141369</iyy>
          <iyz>0</iyz>
          <izz>0.000446429</izz>
        </inertia>
      </inertial>
      <collision name='collision'>
        <pose>0 0 -0.125 1.5708 -0 0</pose>
        <geometry>
          <cylinder>
            <length>0.5</length>
            <radius>0.125</radius>
          </cylinder>
        </geometry>
        <surface>
          <friction>
            <ode>
              <mu>0.5</mu>
              <mu2>0.5</mu2>
            </ode>
          </friction>
          <contact>
            <ode>
              <min_depth>0.01</min_depth>
            </ode>
          </contact>
        </surface>
      </collision>
      <visual name='visual'>
        <pose>0 0 -0.125 1.5708 -0 0</pose>
        <geometry>
          <cylinder>
            <length>0.5</length>
            <radius>0.125</radius>
          </cylinder>
        </geometry>
        <material>
          <ambient>0.3 0.1 0.1 1</ambient>
          <diffuse>0.2 0.2 0.2 1</diffuse>
          <specular>0 0 0 1</specular>
          <emissive>0 0 0 1</emissive>
        </material>
      </visual>
    </link>
    <link name='track_wheel_link2'>
      <pose>0.116667 0 0.125 0 -0 0</pose>
      <inertial>
        <pose>0 0 -0.125 1.5708 -0 0</pose>
        <mass>0.0571429</mass>
        <inertia>
          <ixx>0.00141369</ixx>
          <ixy>0</ixy>
          <ixz>0</ixz>
          <iyy>0.00141369</iyy>
          <iyz>0</iyz>
          <izz>0.000446429</izz>
        </inertia>
      </inertial>
      <collision name='collision'>
        <pose>0 0 -0.125 1.5708 -0 0</pose>
        <geometry>
          <cylinder>
            <length>0.5</length>
            <radius>0.125</radius>
          </cylinder>
        </geometry>
        <surface>
          <friction>
            <ode>
              <mu>0.5</mu>
              <mu2>0.5</mu2>
            </ode>
          </friction>
          <contact>
            <ode>
              <min_depth>0.01</min_depth>
            </ode>
          </contact>
        </surface>
      </collision>
      <visual name='visual'>
        <pose>0 0 -0.125 1.5708 -0 0</pose>
        <geometry>
          <cylinder>
            <length>0.5</length>
            <radius>0.125</radius>
          </cylinder>
        </geometry>
        <material>
          <ambient>0.3 0.1 0.1 1</ambient>
          <diffuse>0.2 0.2 0.2 1</diffuse>
          <specular>0 0 0 1</specular>
          <emissive>0 0 0 1</emissive>
        </material>
      </visual>
    </link>
    <link name='track_wheel_link3'>
      <pose>0 0 0.125 0 -0 0</pose>
      <inertial>
        <pose>0 0 -0.125 1.5708 -0 0</pose>
        <mass>0.0571429</mass>
        <inertia>
          <ixx>0.00141369</ixx>
          <ixy>0</ixy>
          <ixz>0</ixz>
          <iyy>0.00141369</iyy>
          <iyz>0</iyz>
          <izz>0.000446429</izz>
        </inertia>
      </inertial>
      <collision name='collision'>
        <pose>0 0 -0.125 1.5708 -0 0</pose>
        <geometry>
          <cylinder>
            <length>0.5</length>
            <radius>0.125</radius>
          </cylinder>
        </geometry>
        <surface>
          <friction>
            <ode>
              <mu>0.5</mu>
              <mu2>0.5</mu2>
            </ode>
          </friction>
          <contact>
            <ode>
              <min_depth>0.01</min_depth>
            </ode>
          </contact>
        </surface>
      </collision>
      <visual name='visual'>
        <pose>0 0 -0.125 1.5708 -0 0</pose>
        <geometry>
          <cylinder>
            <length>0.5</length>
            <radius>0.125</radius>
          </cylinder>
        </geometry>
        <material>
          <ambient>0.3 0.1 0.1 1</ambient>
          <diffuse>0.2 0.2 0.2 1</diffuse>
          <specular>0 0 0 1</specular>
          <emissive>0 0 0 1</emissive>
        </material>
      </visual>
    </link>
    <link name='track_wheel_link4'>
      <pose>-0.116667 0 0.125 0 -0 0</pose>
      <inertial>
        <pose>0 0 -0.125 1.5708 -0 0</pose>
        <mass>0.0571429</mass>
        <inertia>
          <ixx>0.00141369</ixx>
          <ixy>0</ixy>
          <ixz>0</ixz>
          <iyy>0.00141369</iyy>
          <iyz>0</iyz>
          <izz>0.000446429</izz>
        </inertia>
      </inertial>
      <collision name='collision'>
        <pose>0 0 -0.125 1.5708 -0 0</pose>
        <geometry>
          <cylinder>
            <length>0.5</length>
            <radius>0.125</radius>
          </cylinder>
        </geometry>
        <surface>
          <friction>
            <ode>
              <mu>0.5</mu>
              <mu2>0.5</mu2>
            </ode>
          </friction>
          <contact>
            <ode>
              <min_depth>0.01</min_depth>
            </ode>
          </contact>
        </surface>
      </collision>
      <visual name='visual'>
        <pose>0 0 -0.125 1.5708 -0 0</pose>
        <geometry>
          <cylinder>
            <length>0.5</length>
            <radius>0.125</radius>
          </cylinder>
        </geometry>
        <material>
          <ambient>0.3 0.1 0.1 1</ambient>
          <diffuse>0.2 0.2 0.2 1</diffuse>
          <specular>0 0 0 1</specular>
          <emissive>0 0 0 1</emissive>
        </material>
      </visual>
    </link>
    <link name='track_wheel_link5'>
      <pose>-0.233333 0 0.125 0 -0 0</pose>
      <inertial>
        <pose>0 0 -0.125 1.5708 -0 0</pose>
        <mass>0.0571429</mass>
        <inertia>
          <ixx>0.00141369</ixx>
          <ixy>0</ixy>
          <ixz>0</ixz>
          <iyy>0.00141369</iyy>
          <iyz>0</iyz>
          <izz>0.000446429</izz>
        </inertia>
      </inertial>
      <collision name='collision'>
        <pose>0 0 -0.125 1.5708 -0 0</pose>
        <geometry>
          <cylinder>
            <length>0.5</length>
            <radius>0.125</radius>
          </cylinder>
        </geometry>
        <surface>
          <friction>
            <ode>
              <mu>0.5</mu>
              <mu2>0.5</mu2>
            </ode>
          </friction>
          <contact>
            <ode>
              <min_depth>0.01</min_depth>
            </ode>
          </contact>
        </surface>
      </collision>
      <visual name='visual'>
        <pose>0 0 -0.125 1.5708 -0 0</pose>
        <geometry>
          <cylinder>
            <length>0.5</length>
            <radius>0.125</radius>
          </cylinder>
        </geometry>
        <material>
          <ambient>0.3 0.1 0.1 1</ambient>
          <diffuse>0.2 0.2 0.2 1</diffuse>
          <specular>0 0 0 1</specular>
          <emissive>0 0 0 1</emissive>
        </material>
      </visual>
    </link>
    <link name='track_wheel_link6'>
      <pose>-0.35 0 0.125 0 -0 0</pose>
      <inertial>
        <pose>0 0 -0.125 1.5708 -0 0</pose>
        <mass>0.0571429</mass>
        <inertia>
          <ixx>0.00141369</ixx>
          <ixy>0</ixy>
          <ixz>0</ixz>
          <iyy>0.00141369</iyy>
          <iyz>0</iyz>
          <izz>0.000446429</izz>
        </inertia>
      </inertial>
      <collision name='collision'>
        <pose>0 0 -0.125 1.5708 -0 0</pose>
        <geometry>
          <cylinder>
            <length>0.5</length>
            <radius>0.125</radius>
          </cylinder>
        </geometry>
        <surface>
          <friction>
            <ode>
              <mu>0.5</mu>
              <mu2>0.5</mu2>
            </ode>
          </friction>
          <contact>
            <ode>
              <min_depth>0.01</min_depth>
            </ode>
          </contact>
        </surface>
      </collision>
      <visual name='visual'>
        <pose>0 0 -0.125 1.5708 -0 0</pose>
        <geometry>
          <cylinder>
            <length>0.5</length>
            <radius>0.125</radius>
          </cylinder>
        </geometry>
        <material>
          <ambient>0.3 0.1 0.1 1</ambient>
          <diffuse>0.2 0.2 0.2 1</diffuse>
          <specular>0 0 0 1</specular>
          <emissive>0 0 0 1</emissive>
        </material>
      </visual>
    </link>
    <joint name='track_wheel_joint0' type='revolute'>
      <child>track_wheel_link0</child>
      <parent>body</parent>
      <pose>0 0 -0.125 0 -0 0</pose>
      <axis>
        <xyz>0 1 0</xyz>
        <use_parent_model_frame>0</use_parent_model_frame>
        <limit>
          <lower>-1e+16</lower>
          <upper>1e+16</upper>
        </limit>
      </axis>
      <physics>
        <ode>
          <implicit_spring_damper>1</implicit_spring_damper>
        </ode>
      </physics>
    </joint>
    <joint name='track_wheel_joint1' type='revolute'>
      <child>track_wheel_link1</child>
      <parent>body</parent>
      <pose>0 0 -0.125 0 -0 0</pose>
      <axis>
        <xyz>0 1 0</xyz>
        <use_parent_model_frame>0</use_parent_model_frame>
        <limit>
          <lower>-1e+16</lower>
          <upper>1e+16</upper>
        </limit>
      </axis>
      <physics>
        <ode>
          <implicit_spring_damper>1</implicit_spring_damper>
        </ode>
      </physics>
    </joint>
    <joint name='track_wheel_joint2' type='revolute'>
      <child>track_wheel_link2</child>
      <parent>body</parent>
      <pose>0 0 -0.125 0 -0 0</pose>
      <axis>
        <xyz>0 1 0</xyz>
        <use_parent_model_frame>0</use_parent_model_frame>
        <limit>
          <lower>-1e+16</lower>
          <upper>1e+16</upper>
        </limit>
      </axis>
      <physics>
        <ode>
          <implicit_spring_damper>1</implicit_spring_damper>
        </ode>
      </physics>
    </joint>
    <joint name='track_wheel_joint3' type='revolute'>
      <child>track_wheel_link3</child>
      <parent>body</parent>
      <pose>0 0 -0.125 0 -0 0</pose>
      <axis>
        <xyz>0 1 0</xyz>
        <use_parent_model_frame>0</use_parent_model_frame>
        <limit>
          <lower>-1e+16</lower>
          <upper>1e+16</upper>
        </limit>
      </axis>
      <physics>
        <ode>
          <implicit_spring_damper>1</implicit_spring_damper>
        </ode>
      </physics>
    </joint>
    <joint name='track_wheel_joint4' type='revolute'>
      <child>track_wheel_link4</child>
      <parent>body</parent>
      <pose>0 0 -0.125 0 -0 0</pose>
      <axis>
        <xyz>0 1 0</xyz>
        <use_parent_model_frame>0</use_parent_model_frame>
        <limit>
          <lower>-1e+16</lower>
          <upper>1e+16</upper>
        </limit>
      </axis>
      <physics>
        <ode>
          <implicit_spring_damper>1</implicit_spring_damper>
        </ode>
      </physics>
    </joint>
    <joint name='track_wheel_joint5' type='revolute'>
      <child>track_wheel_link5</child>
      <parent>body</parent>
      <pose>0 0 -0.125 0 -0 0</pose>
      <axis>
        <xyz>0 1 0</xyz>
        <use_parent_model_frame>0</use_parent_model_frame>
        <limit>
          <lower>-1e+16</lower>
          <upper>1e+16</upper>
        </limit>
      </axis>
      <physics>
        <ode>
          <implicit_spring_damper>1</implicit_spring_damper>
        </ode>
      </physics>
    </joint>
    <joint name='track_wheel_joint6' type='revolute'>
      <child>track_wheel_link6</child>
      <parent>body</parent>
      <pose>0 0 -0.125 0 -0 0</pose>
      <axis>
        <xyz>0 1 0</xyz>
        <use_parent_model_frame>0</use_parent_model_frame>
        <limit>
          <lower>-1e+16</lower>
          <upper>1e+16</upper>
        </limit>
      </axis>
      <physics>
        <ode>
          <implicit_spring_damper>1</implicit_spring_damper>
        </ode>
      </physics>
    </joint>
    <plugin name='track' filename='libContinuousTrackSimple.so'>
      <sprocket>
        <joint>sprocket_axle</joint>
        <pitch_diameter>0.24</pitch_diameter>
      </sprocket>
      <track>
        <segment>
          <joint>track_wheel_joint0</joint>
          <pitch_diameter>0.24</pitch_diameter>
        </segment>
        <segment>
          <joint>track_wheel_joint1</joint>
          <pitch_diameter>0.24</pitch_diameter>
        </segment>
        <segment>
          <joint>track_wheel_joint2</joint>
          <pitch_diameter>0.24</pitch_diameter>
        </segment>
        <segment>
          <joint>track_wheel_joint3</joint>
          <pitch_diameter>0.24</pitch_diameter>
        </segment>
        <segment>
          <joint>track_wheel_joint4</joint>
          <pitch_diameter>0.24</pitch_diameter>
        </segment>
        <segment>
          <joint>track_wheel_joint5</joint>
          <pitch_diameter>0.24</pitch_diameter>
        </segment>
        <segment>
          <joint>track_wheel_joint6</joint>
          <pitch_diameter>0.24</pitch_diameter>
        </segment>
      </track>
    </plugin>
    <static>0</static>
    <plugin name='gazebo_ros_control' filename='libgazebo_ros_control.so'>
      <robotSimType>gazebo_ros_control/DefaultRobotHWSim</robotSimType>
      <legacyModeNS>0</legacyModeNS>
    </plugin>
  </model>
</sdf>
