<?xml version="1.0" ?>
<!-- =================================================================================== -->
<!-- |    This document was autogenerated by xacro from urdf_xacro/example_track_simple_wheels_gazebo.urdf.xacro | -->
<!-- |    EDITING THIS FILE BY HAND IS NOT RECOMMENDED                                 | -->
<!-- =================================================================================== -->
<robot name="example_track_simple_wheels">
  <!-- -->
  <!--                                                                                              -->
  <!-- macros for making simple track                                                               -->
  <!--     * useful when difining entities for ContinuousTrackSimple plugin                         -->
  <!--     * see gazebo_continuous_track_example/urdf/example_track_simple.urdf.xacro to know usage -->
  <!--                                                                                              -->
  <!-- macros which expand to inertial/collision/visual -->
  <!-- macros which expand to box/polyline collision and visual. convenient when defining pattern elements on a track -->
  <!-- macros for populating general links/joints -->
  <!-- track segment templates which can be used with above population macros -->
  <!-- macros for populating track segments with above population macros and above templates -->
  <!-- macro which expands to simple plugin definition -->
  <!-- main entry point: macro for making oval track by ContinuousTrackSimple plugin -->
  <!-- URDF file for general ROS systems such as ros_control, rviz, etc.           -->
  <!-- We define here;                                                             -->
  <!--     * a base_link to be wrapped by the track                                     -->
  <!--     * a sprocket to drive the track                                         -->
  <!--     * an axle and actuator for the sprocket                                 -->
  <!--     * an idler wheel on the other side of the sprocket                      -->
  <!-- Other entities specialized for Gazebo are defined in *_gazebo.urdf.xacro .  -->
  <!-- base_link to be wrapped by the track -->
  <link name="base_link">
    <inertial>
      <mass value="1"/>
      <inertia ixx="0.009635416666666667" ixy="0" ixz="0" iyy="0.021666666666666667" iyz="0" izz="0.029635416666666668"/>
    </inertial>
    <visual>
      <geometry>
        <box size="0.1 0.1 0.1"/>
      </geometry>
    </visual>
    <collision>
      <geometry>
        <box size="0.1 0.1 0.1"/>
      </geometry>
    </collision>
  </link>
  <!-- sprocket driving the track -->
  <link name="sprocket_left">
    <inertial>
      <mass value="0.2"/>
      <!-- assuming axis of cylinder is y, not z -->
      <inertia ixx="0.0004120041666666667" ixy="0" ixz="0" iyy="0.00040960000000000004" iyz="0" izz="0.0004120041666666667"/>
    </inertial>
    <visual>
      <origin rpy="1.5707963267948966 0 0" xyz="0 0 0"/>
      <geometry>
        <cylinder length="0.1115" radius="0.064"/>
      </geometry>
    </visual>
    <visual>
      <geometry>
        <box size="0.01 0.1115 0.1"/>
      </geometry>
    </visual>
    <visual>
      <geometry>
        <box size="0.1 0.1115 0.01"/>
      </geometry>
    </visual>
    <collision>
      <origin rpy="1.5707963267948966 0 0" xyz="0 0 0"/>
      <geometry>
        <cylinder length="0.1115" radius="0.064"/>
      </geometry>
    </collision>
  </link>
  <joint name="sprocket_left_axle" type="continuous">
    <origin rpy="0 0 0" xyz="0.2 0.095 0"/>
    <parent link="base_link"/>
    <child link="sprocket_left"/>
    <axis xyz="0 1 0"/>
  </joint>
  <transmission name="sprocket_left_transmission">
    <type>transmission_interface/SimpleTransmission</type>
    <joint name="sprocket_left_axle">
      <hardwareInterface>hardware_interface/VelocityJointInterface</hardwareInterface>
    </joint>
    <actuator name="sprocket_left_actuator">
      <mechanicalReduction>1</mechanicalReduction>
    </actuator>
  </transmission>
  <!-- idler on the other side of the sprocket -->
  <link name="idler_left">
    <inertial>
      <mass value="0.2"/>
      <!-- assuming axis of cylinder is y, not z -->
      <inertia ixx="0.0004120041666666667" ixy="0" ixz="0" iyy="0.00040960000000000004" iyz="0" izz="0.0004120041666666667"/>
    </inertial>
    <visual>
      <origin rpy="1.5707963267948966 0 0" xyz="0 0 0"/>
      <geometry>
        <cylinder length="0.1115" radius="0.064"/>
      </geometry>
    </visual>
    <collision>
      <origin rpy="1.5707963267948966 0 0" xyz="0 0 0"/>
      <geometry>
        <cylinder length="0.1115" radius="0.064"/>
      </geometry>
    </collision>
  </link>
  <joint name="idler_left_axle" type="fixed">
    <origin rpy="0 0 0" xyz="-0.2 0.095 0"/>
    <parent link="base_link"/>
    <child link="idler_left"/>
  </joint>
  <!-- sprocket driving the track -->
  <link name="sprocket_right">
    <inertial>
      <mass value="0.2"/>
      <!-- assuming axis of cylinder is y, not z -->
      <inertia ixx="0.0004120041666666667" ixy="0" ixz="0" iyy="0.00040960000000000004" iyz="0" izz="0.0004120041666666667"/>
    </inertial>
    <visual>
      <origin rpy="1.5707963267948966 0 0" xyz="0 0 0"/>
      <geometry>
        <cylinder length="0.1115" radius="0.064"/>
      </geometry>
    </visual>
    <visual>
      <geometry>
        <box size="0.01 0.1115 0.1"/>
      </geometry>
    </visual>
    <visual>
      <geometry>
        <box size="0.1 0.1115 0.01"/>
      </geometry>
    </visual>
    <collision>
      <origin rpy="1.5707963267948966 0 0" xyz="0 0 0"/>
      <geometry>
        <cylinder length="0.1115" radius="0.064"/>
      </geometry>
    </collision>
  </link>
  <joint name="sprocket_right_axle" type="continuous">
    <origin rpy="0 0 0" xyz="0.2 -0.095 0"/>
    <parent link="base_link"/>
    <child link="sprocket_right"/>
    <axis xyz="0 1 0"/>
  </joint>
  <transmission name="sprocket_right_transmission">
    <type>transmission_interface/SimpleTransmission</type>
    <joint name="sprocket_right_axle">
      <hardwareInterface>hardware_interface/VelocityJointInterface</hardwareInterface>
    </joint>
    <actuator name="sprocket_right_actuator">
      <mechanicalReduction>1</mechanicalReduction>
    </actuator>
  </transmission>
  <!-- idler on the other side of the sprocket -->
  <link name="idler_right">
    <inertial>
      <mass value="0.2"/>
      <!-- assuming axis of cylinder is y, not z -->
      <inertia ixx="0.0004120041666666667" ixy="0" ixz="0" iyy="0.00040960000000000004" iyz="0" izz="0.0004120041666666667"/>
    </inertial>
    <visual>
      <origin rpy="1.5707963267948966 0 0" xyz="0 0 0"/>
      <geometry>
        <cylinder length="0.1115" radius="0.064"/>
      </geometry>
    </visual>
    <collision>
      <origin rpy="1.5707963267948966 0 0" xyz="0 0 0"/>
      <geometry>
        <cylinder length="0.1115" radius="0.064"/>
      </geometry>
    </collision>
  </link>
  <joint name="idler_right_axle" type="fixed">
    <origin rpy="0 0 0" xyz="-0.2 -0.095 0"/>
    <parent link="base_link"/>
    <child link="idler_right"/>
  </joint>
  <!-- -->
  <gazebo>
    <link name="track_wheel_link0">
      <pose>0.35 0 0.125 0 0 0</pose>
      <inertial>
        <pose>0 0 -0.125 1.5707963267948966 0 0</pose>
        <mass>0.05714285714285715</mass>
        <inertia>
          <ixx>0.0014136904761904762</ixx>
          <ixy>0</ixy>
          <ixz>0</ixz>
          <iyy>0.0014136904761904762</iyy>
          <iyz>0</iyz>
          <izz>0.00044642857142857147</izz>
        </inertia>
      </inertial>
      <collision name="collision">
        <pose>0 0 -0.125 1.5707963267948966 0 0</pose>
        <geometry>
          <cylinder>
            <length>0.5</length>
            <radius>0.125</radius>
          </cylinder>
        </geometry>
        <surface>
          <friction>
            <ode>
              <mu>0.5</mu>
              <mu2>0.5</mu2>
            </ode>
          </friction>
          <contact>
            <ode>
              <min_depth>0.01</min_depth>
            </ode>
          </contact>
        </surface>
      </collision>
      <visual name="visual">
        <pose>0 0 -0.125 1.5707963267948966 0 0</pose>
        <geometry>
          <cylinder>
            <length>0.5</length>
            <radius>0.125</radius>
          </cylinder>
        </geometry>
        <material>
          <ambient>0.3 0.1 0.1 1</ambient>
          <diffuse>0.2 0.2 0.2 1</diffuse>
          <specular>0 0 0 1</specular>
          <emissive>0 0 0 1</emissive>
        </material>
      </visual>
    </link>
  </gazebo>
  <gazebo>
    <link name="track_wheel_link1">
      <pose>0.23333333333333334 0 0.125 0 0 0</pose>
      <inertial>
        <pose>0 0 -0.125 1.5707963267948966 0 0</pose>
        <mass>0.05714285714285715</mass>
        <inertia>
          <ixx>0.0014136904761904762</ixx>
          <ixy>0</ixy>
          <ixz>0</ixz>
          <iyy>0.0014136904761904762</iyy>
          <iyz>0</iyz>
          <izz>0.00044642857142857147</izz>
        </inertia>
      </inertial>
      <collision name="collision">
        <pose>0 0 -0.125 1.5707963267948966 0 0</pose>
        <geometry>
          <cylinder>
            <length>0.5</length>
            <radius>0.125</radius>
          </cylinder>
        </geometry>
        <surface>
          <friction>
            <ode>
              <mu>0.5</mu>
              <mu2>0.5</mu2>
            </ode>
          </friction>
          <contact>
            <ode>
              <min_depth>0.01</min_depth>
            </ode>
          </contact>
        </surface>
      </collision>
      <visual name="visual">
        <pose>0 0 -0.125 1.5707963267948966 0 0</pose>
        <geometry>
          <cylinder>
            <length>0.5</length>
            <radius>0.125</radius>
          </cylinder>
        </geometry>
        <material>
          <ambient>0.3 0.1 0.1 1</ambient>
          <diffuse>0.2 0.2 0.2 1</diffuse>
          <specular>0 0 0 1</specular>
          <emissive>0 0 0 1</emissive>
        </material>
      </visual>
    </link>
  </gazebo>
  <gazebo>
    <link name="track_wheel_link2">
      <pose>0.11666666666666668 0 0.125 0 0 0</pose>
      <inertial>
        <pose>0 0 -0.125 1.5707963267948966 0 0</pose>
        <mass>0.05714285714285715</mass>
        <inertia>
          <ixx>0.0014136904761904762</ixx>
          <ixy>0</ixy>
          <ixz>0</ixz>
          <iyy>0.0014136904761904762</iyy>
          <iyz>0</iyz>
          <izz>0.00044642857142857147</izz>
        </inertia>
      </inertial>
      <collision name="collision">
        <pose>0 0 -0.125 1.5707963267948966 0 0</pose>
        <geometry>
          <cylinder>
            <length>0.5</length>
            <radius>0.125</radius>
          </cylinder>
        </geometry>
        <surface>
          <friction>
            <ode>
              <mu>0.5</mu>
              <mu2>0.5</mu2>
            </ode>
          </friction>
          <contact>
            <ode>
              <min_depth>0.01</min_depth>
            </ode>
          </contact>
        </surface>
      </collision>
      <visual name="visual">
        <pose>0 0 -0.125 1.5707963267948966 0 0</pose>
        <geometry>
          <cylinder>
            <length>0.5</length>
            <radius>0.125</radius>
          </cylinder>
        </geometry>
        <material>
          <ambient>0.3 0.1 0.1 1</ambient>
          <diffuse>0.2 0.2 0.2 1</diffuse>
          <specular>0 0 0 1</specular>
          <emissive>0 0 0 1</emissive>
        </material>
      </visual>
    </link>
  </gazebo>
  <gazebo>
    <link name="track_wheel_link3">
      <pose>2.7755575615628914e-17 0 0.125 0 0 0</pose>
      <inertial>
        <pose>0 0 -0.125 1.5707963267948966 0 0</pose>
        <mass>0.05714285714285715</mass>
        <inertia>
          <ixx>0.0014136904761904762</ixx>
          <ixy>0</ixy>
          <ixz>0</ixz>
          <iyy>0.0014136904761904762</iyy>
          <iyz>0</iyz>
          <izz>0.00044642857142857147</izz>
        </inertia>
      </inertial>
      <collision name="collision">
        <pose>0 0 -0.125 1.5707963267948966 0 0</pose>
        <geometry>
          <cylinder>
            <length>0.5</length>
            <radius>0.125</radius>
          </cylinder>
        </geometry>
        <surface>
          <friction>
            <ode>
              <mu>0.5</mu>
              <mu2>0.5</mu2>
            </ode>
          </friction>
          <contact>
            <ode>
              <min_depth>0.01</min_depth>
            </ode>
          </contact>
        </surface>
      </collision>
      <visual name="visual">
        <pose>0 0 -0.125 1.5707963267948966 0 0</pose>
        <geometry>
          <cylinder>
            <length>0.5</length>
            <radius>0.125</radius>
          </cylinder>
        </geometry>
        <material>
          <ambient>0.3 0.1 0.1 1</ambient>
          <diffuse>0.2 0.2 0.2 1</diffuse>
          <specular>0 0 0 1</specular>
          <emissive>0 0 0 1</emissive>
        </material>
      </visual>
    </link>
  </gazebo>
  <gazebo>
    <link name="track_wheel_link4">
      <pose>-0.11666666666666663 0 0.125 0 0 0</pose>
      <inertial>
        <pose>0 0 -0.125 1.5707963267948966 0 0</pose>
        <mass>0.05714285714285715</mass>
        <inertia>
          <ixx>0.0014136904761904762</ixx>
          <ixy>0</ixy>
          <ixz>0</ixz>
          <iyy>0.0014136904761904762</iyy>
          <iyz>0</iyz>
          <izz>0.00044642857142857147</izz>
        </inertia>
      </inertial>
      <collision name="collision">
        <pose>0 0 -0.125 1.5707963267948966 0 0</pose>
        <geometry>
          <cylinder>
            <length>0.5</length>
            <radius>0.125</radius>
          </cylinder>
        </geometry>
        <surface>
          <friction>
            <ode>
              <mu>0.5</mu>
              <mu2>0.5</mu2>
            </ode>
          </friction>
          <contact>
            <ode>
              <min_depth>0.01</min_depth>
            </ode>
          </contact>
        </surface>
      </collision>
      <visual name="visual">
        <pose>0 0 -0.125 1.5707963267948966 0 0</pose>
        <geometry>
          <cylinder>
            <length>0.5</length>
            <radius>0.125</radius>
          </cylinder>
        </geometry>
        <material>
          <ambient>0.3 0.1 0.1 1</ambient>
          <diffuse>0.2 0.2 0.2 1</diffuse>
          <specular>0 0 0 1</specular>
          <emissive>0 0 0 1</emissive>
        </material>
      </visual>
    </link>
  </gazebo>
  <gazebo>
    <link name="track_wheel_link5">
      <pose>-0.23333333333333328 0 0.125 0 0 0</pose>
      <inertial>
        <pose>0 0 -0.125 1.5707963267948966 0 0</pose>
        <mass>0.05714285714285715</mass>
        <inertia>
          <ixx>0.0014136904761904762</ixx>
          <ixy>0</ixy>
          <ixz>0</ixz>
          <iyy>0.0014136904761904762</iyy>
          <iyz>0</iyz>
          <izz>0.00044642857142857147</izz>
        </inertia>
      </inertial>
      <collision name="collision">
        <pose>0 0 -0.125 1.5707963267948966 0 0</pose>
        <geometry>
          <cylinder>
            <length>0.5</length>
            <radius>0.125</radius>
          </cylinder>
        </geometry>
        <surface>
          <friction>
            <ode>
              <mu>0.5</mu>
              <mu2>0.5</mu2>
            </ode>
          </friction>
          <contact>
            <ode>
              <min_depth>0.01</min_depth>
            </ode>
          </contact>
        </surface>
      </collision>
      <visual name="visual">
        <pose>0 0 -0.125 1.5707963267948966 0 0</pose>
        <geometry>
          <cylinder>
            <length>0.5</length>
            <radius>0.125</radius>
          </cylinder>
        </geometry>
        <material>
          <ambient>0.3 0.1 0.1 1</ambient>
          <diffuse>0.2 0.2 0.2 1</diffuse>
          <specular>0 0 0 1</specular>
          <emissive>0 0 0 1</emissive>
        </material>
      </visual>
    </link>
  </gazebo>
  <gazebo>
    <link name="track_wheel_link6">
      <pose>-0.3499999999999999 0 0.125 0 0 0</pose>
      <inertial>
        <pose>0 0 -0.125 1.5707963267948966 0 0</pose>
        <mass>0.05714285714285715</mass>
        <inertia>
          <ixx>0.0014136904761904762</ixx>
          <ixy>0</ixy>
          <ixz>0</ixz>
          <iyy>0.0014136904761904762</iyy>
          <iyz>0</iyz>
          <izz>0.00044642857142857147</izz>
        </inertia>
      </inertial>
      <collision name="collision">
        <pose>0 0 -0.125 1.5707963267948966 0 0</pose>
        <geometry>
          <cylinder>
            <length>0.5</length>
            <radius>0.125</radius>
          </cylinder>
        </geometry>
        <surface>
          <friction>
            <ode>
              <mu>0.5</mu>
              <mu2>0.5</mu2>
            </ode>
          </friction>
          <contact>
            <ode>
              <min_depth>0.01</min_depth>
            </ode>
          </contact>
        </surface>
      </collision>
      <visual name="visual">
        <pose>0 0 -0.125 1.5707963267948966 0 0</pose>
        <geometry>
          <cylinder>
            <length>0.5</length>
            <radius>0.125</radius>
          </cylinder>
        </geometry>
        <material>
          <ambient>0.3 0.1 0.1 1</ambient>
          <diffuse>0.2 0.2 0.2 1</diffuse>
          <specular>0 0 0 1</specular>
          <emissive>0 0 0 1</emissive>
        </material>
      </visual>
    </link>
  </gazebo>
  <gazebo>
    <joint name="track_wheel_joint0" type="revolute">
      <child>track_wheel_link0</child>
      <parent>body</parent>
      <pose>0 0 -0.125 0 0 0</pose>
      <axis>
        <xyz>0 1 0</xyz>
        <use_parent_model_frame>0</use_parent_model_frame>
      </axis>
      <physics>
        <ode>
          <implicit_spring_damper>1</implicit_spring_damper>
        </ode>
      </physics>
    </joint>
  </gazebo>
  <gazebo>
    <joint name="track_wheel_joint1" type="revolute">
      <child>track_wheel_link1</child>
      <parent>body</parent>
      <pose>0 0 -0.125 0 0 0</pose>
      <axis>
        <xyz>0 1 0</xyz>
        <use_parent_model_frame>0</use_parent_model_frame>
      </axis>
      <physics>
        <ode>
          <implicit_spring_damper>1</implicit_spring_damper>
        </ode>
      </physics>
    </joint>
  </gazebo>
  <gazebo>
    <joint name="track_wheel_joint2" type="revolute">
      <child>track_wheel_link2</child>
      <parent>body</parent>
      <pose>0 0 -0.125 0 0 0</pose>
      <axis>
        <xyz>0 1 0</xyz>
        <use_parent_model_frame>0</use_parent_model_frame>
      </axis>
      <physics>
        <ode>
          <implicit_spring_damper>1</implicit_spring_damper>
        </ode>
      </physics>
    </joint>
  </gazebo>
  <gazebo>
    <joint name="track_wheel_joint3" type="revolute">
      <child>track_wheel_link3</child>
      <parent>body</parent>
      <pose>0 0 -0.125 0 0 0</pose>
      <axis>
        <xyz>0 1 0</xyz>
        <use_parent_model_frame>0</use_parent_model_frame>
      </axis>
      <physics>
        <ode>
          <implicit_spring_damper>1</implicit_spring_damper>
        </ode>
      </physics>
    </joint>
  </gazebo>
  <gazebo>
    <joint name="track_wheel_joint4" type="revolute">
      <child>track_wheel_link4</child>
      <parent>body</parent>
      <pose>0 0 -0.125 0 0 0</pose>
      <axis>
        <xyz>0 1 0</xyz>
        <use_parent_model_frame>0</use_parent_model_frame>
      </axis>
      <physics>
        <ode>
          <implicit_spring_damper>1</implicit_spring_damper>
        </ode>
      </physics>
    </joint>
  </gazebo>
  <gazebo>
    <joint name="track_wheel_joint5" type="revolute">
      <child>track_wheel_link5</child>
      <parent>body</parent>
      <pose>0 0 -0.125 0 0 0</pose>
      <axis>
        <xyz>0 1 0</xyz>
        <use_parent_model_frame>0</use_parent_model_frame>
      </axis>
      <physics>
        <ode>
          <implicit_spring_damper>1</implicit_spring_damper>
        </ode>
      </physics>
    </joint>
  </gazebo>
  <gazebo>
    <joint name="track_wheel_joint6" type="revolute">
      <child>track_wheel_link6</child>
      <parent>body</parent>
      <pose>0 0 -0.125 0 0 0</pose>
      <axis>
        <xyz>0 1 0</xyz>
        <use_parent_model_frame>0</use_parent_model_frame>
      </axis>
      <physics>
        <ode>
          <implicit_spring_damper>1</implicit_spring_damper>
        </ode>
      </physics>
    </joint>
  </gazebo>
  <gazebo>
    <plugin filename="libContinuousTrackSimple.so" name="track">
      <sprocket>
        <joint>sprocket_axle</joint>
        <pitch_diameter>0.24</pitch_diameter>
      </sprocket>
      <track>
        <segment>
          <joint>track_wheel_joint0</joint>
          <pitch_diameter>0.24</pitch_diameter>
        </segment>
        <segment>
          <joint>track_wheel_joint1</joint>
          <pitch_diameter>0.24</pitch_diameter>
        </segment>
        <segment>
          <joint>track_wheel_joint2</joint>
          <pitch_diameter>0.24</pitch_diameter>
        </segment>
        <segment>
          <joint>track_wheel_joint3</joint>
          <pitch_diameter>0.24</pitch_diameter>
        </segment>
        <segment>
          <joint>track_wheel_joint4</joint>
          <pitch_diameter>0.24</pitch_diameter>
        </segment>
        <segment>
          <joint>track_wheel_joint5</joint>
          <pitch_diameter>0.24</pitch_diameter>
        </segment>
        <segment>
          <joint>track_wheel_joint6</joint>
          <pitch_diameter>0.24</pitch_diameter>
        </segment>
      </track>
    </plugin>
  </gazebo>
  <!-- ros_control for gazebo -->
  <gazebo>
    <plugin filename="libgazebo_ros_control.so" name="gazebo_ros_control">
      <robotSimType>gazebo_ros_control/DefaultRobotHWSim</robotSimType>
      <legacyModeNS>false</legacyModeNS>
    </plugin>
  </gazebo>
</robot>
