<?xml version="1.0" ?>
<!-- =================================================================================== -->
<!-- |    This document was autogenerated by xacro from urdf_xacro/example_track_gazebo.urdf.xacro | -->
<!-- |    EDITING THIS FILE BY HAND IS NOT RECOMMENDED                                 | -->
<!-- =================================================================================== -->
<robot name="example_track">
  <!-- -->
  <!--                                                                                       -->
  <!-- macros for making track                                                               -->
  <!--     * useful when difining entities for ContinuousTrack plugin                        -->
  <!--     * see gazebo_continuous_track_example/urdf/example_track.urdf.xacro to know usage -->
  <!--                                                                                       -->
  <!-- macros which expand to inertial/collision/visual -->
  <!-- macros which expand to box/polyline collision and visual. convenient when defining pattern elements on a track -->
  <!-- track segment templates which can be used with above population macros -->
  <!-- macros for populating track segments with above population macros and above templates -->
  <!-- macro which expands to plugin definition -->
  <!-- main entry point: macro for making oval track by ContinuousTrack plugin -->
  <!-- URDF file for general ROS systems such as ros_control, rviz, etc.           -->
  <!-- We define here;                                                             -->
  <!--     * a base_link to be wrapped by the track                                     -->
  <!--     * a sprocket to drive the track                                         -->
  <!--     * an axle and actuator for the sprocket                                 -->
  <!--     * an idler wheel on the other side of the sprocket                      -->
  <!-- Other entities specialized for Gazebo are defined in *_gazebo.urdf.xacro .  -->
  <!-- base_link to be wrapped by the track -->
  <link name="base_link">
    <inertial>
      <mass value="1"/>
      <inertia ixx="0.009635416666666667" ixy="0" ixz="0" iyy="0.021666666666666667" iyz="0" izz="0.029635416666666668"/>
    </inertial>
    <visual>
      <geometry>
        <box size="0.1 0.1 0.1"/>
      </geometry>
    </visual>
    <collision>
      <geometry>
        <box size="0.1 0.1 0.1"/>
      </geometry>
    </collision>
  </link>
  <!-- sprocket driving the track -->
  <link name="sprocket_left">
    <inertial>
      <mass value="0.2"/>
      <!-- assuming axis of cylinder is y, not z -->
      <inertia ixx="0.0004120041666666667" ixy="0" ixz="0" iyy="0.00040960000000000004" iyz="0" izz="0.0004120041666666667"/>
    </inertial>
    <visual>
      <origin rpy="1.5707963267948966 0 0" xyz="0 0 0"/>
      <geometry>
        <cylinder length="0.1115" radius="0.064"/>
      </geometry>
    </visual>
    <visual>
      <geometry>
        <box size="0.01 0.1115 0.1"/>
      </geometry>
    </visual>
    <visual>
      <geometry>
        <box size="0.1 0.1115 0.01"/>
      </geometry>
    </visual>
    <collision>
      <origin rpy="1.5707963267948966 0 0" xyz="0 0 0"/>
      <geometry>
        <cylinder length="0.1115" radius="0.064"/>
      </geometry>
    </collision>
  </link>
  <joint name="sprocket_left_axle" type="continuous">
    <origin rpy="0 0 0" xyz="0.2 0.095 0"/>
    <parent link="base_link"/>
    <child link="sprocket_left"/>
    <axis xyz="0 1 0"/>
  </joint>
  <transmission name="sprocket_left_transmission">
    <type>transmission_interface/SimpleTransmission</type>
    <joint name="sprocket_left_axle">
      <hardwareInterface>hardware_interface/VelocityJointInterface</hardwareInterface>
    </joint>
    <actuator name="sprocket_left_actuator">
      <mechanicalReduction>1</mechanicalReduction>
    </actuator>
  </transmission>
  <!-- idler on the other side of the sprocket -->
  <link name="idler_left">
    <inertial>
      <mass value="0.2"/>
      <!-- assuming axis of cylinder is y, not z -->
      <inertia ixx="0.0004120041666666667" ixy="0" ixz="0" iyy="0.00040960000000000004" iyz="0" izz="0.0004120041666666667"/>
    </inertial>
    <visual>
      <origin rpy="1.5707963267948966 0 0" xyz="0 0 0"/>
      <geometry>
        <cylinder length="0.1115" radius="0.064"/>
      </geometry>
    </visual>
    <collision>
      <origin rpy="1.5707963267948966 0 0" xyz="0 0 0"/>
      <geometry>
        <cylinder length="0.1115" radius="0.064"/>
      </geometry>
    </collision>
  </link>
  <joint name="idler_left_axle" type="fixed">
    <origin rpy="0 0 0" xyz="-0.2 0.095 0"/>
    <parent link="base_link"/>
    <child link="idler_left"/>
  </joint>
  <!-- sprocket driving the track -->
  <link name="sprocket_right">
    <inertial>
      <mass value="0.2"/>
      <!-- assuming axis of cylinder is y, not z -->
      <inertia ixx="0.0004120041666666667" ixy="0" ixz="0" iyy="0.00040960000000000004" iyz="0" izz="0.0004120041666666667"/>
    </inertial>
    <visual>
      <origin rpy="1.5707963267948966 0 0" xyz="0 0 0"/>
      <geometry>
        <cylinder length="0.1115" radius="0.064"/>
      </geometry>
    </visual>
    <visual>
      <geometry>
        <box size="0.01 0.1115 0.1"/>
      </geometry>
    </visual>
    <visual>
      <geometry>
        <box size="0.1 0.1115 0.01"/>
      </geometry>
    </visual>
    <collision>
      <origin rpy="1.5707963267948966 0 0" xyz="0 0 0"/>
      <geometry>
        <cylinder length="0.1115" radius="0.064"/>
      </geometry>
    </collision>
  </link>
  <joint name="sprocket_right_axle" type="continuous">
    <origin rpy="0 0 0" xyz="0.2 -0.095 0"/>
    <parent link="base_link"/>
    <child link="sprocket_right"/>
    <axis xyz="0 1 0"/>
  </joint>
  <transmission name="sprocket_right_transmission">
    <type>transmission_interface/SimpleTransmission</type>
    <joint name="sprocket_right_axle">
      <hardwareInterface>hardware_interface/VelocityJointInterface</hardwareInterface>
    </joint>
    <actuator name="sprocket_right_actuator">
      <mechanicalReduction>1</mechanicalReduction>
    </actuator>
  </transmission>
  <!-- idler on the other side of the sprocket -->
  <link name="idler_right">
    <inertial>
      <mass value="0.2"/>
      <!-- assuming axis of cylinder is y, not z -->
      <inertia ixx="0.0004120041666666667" ixy="0" ixz="0" iyy="0.00040960000000000004" iyz="0" izz="0.0004120041666666667"/>
    </inertial>
    <visual>
      <origin rpy="1.5707963267948966 0 0" xyz="0 0 0"/>
      <geometry>
        <cylinder length="0.1115" radius="0.064"/>
      </geometry>
    </visual>
    <collision>
      <origin rpy="1.5707963267948966 0 0" xyz="0 0 0"/>
      <geometry>
        <cylinder length="0.1115" radius="0.064"/>
      </geometry>
    </collision>
  </link>
  <joint name="idler_right_axle" type="fixed">
    <origin rpy="0 0 0" xyz="-0.2 -0.095 0"/>
    <parent link="base_link"/>
    <child link="idler_right"/>
  </joint>
  <!-- -->
  <gazebo>
    <link name="track_left_straight_segment_link0">
      <pose>-0.2 0.095 0.064 0 0.0 0</pose>
      <inertial>
        <pose>0.2 0 -0.032 0 0 0</pose>
        <mass>0.1</mass>
        <inertia>
          <ixx>0.00013773541666666669</ixx>
          <ixy>0</ixy>
          <ixz>0</ixz>
          <iyy>0.0013674666666666669</iyy>
          <iyz>0</iyz>
          <izz>0.001436935416666667</izz>
        </inertia>
      </inertial>
      <collision name="collision">
        <pose>0.2 0 -0.032 0 0 0</pose>
        <geometry>
          <box>
            <size>0.4 0.1115 0.064</size>
          </box>
        </geometry>
        <surface>
          <friction>
            <ode>
              <mu>1000000</mu>
              <mu2>1000000</mu2>
            </ode>
          </friction>
          <contact>
            <ode>
              <min_depth>0.01</min_depth>
              <max_vel>0</max_vel>
            </ode>
          </contact>
        </surface>
      </collision>
      <visual name="visual">
        <pose>0.2 0 -0.032 0 0 0</pose>
        <geometry>
          <box>
            <size>0.4 0.1115 0.064</size>
          </box>
        </geometry>
        <material>
          <ambient>0.1 0.1 0.3 1</ambient>
          <diffuse>0.2 0.2 0.2 1</diffuse>
          <specular>0 0 0 1</specular>
          <emissive>0 0 0 1</emissive>
        </material>
      </visual>
    </link>
  </gazebo>
  <gazebo>
    <link name="track_left_straight_segment_link1">
      <pose>0.2 0.095 -0.064 0 3.141592653589793 0</pose>
      <inertial>
        <pose>0.2 0 -0.032 0 0 0</pose>
        <mass>0.1</mass>
        <inertia>
          <ixx>0.00013773541666666669</ixx>
          <ixy>0</ixy>
          <ixz>0</ixz>
          <iyy>0.0013674666666666669</iyy>
          <iyz>0</iyz>
          <izz>0.001436935416666667</izz>
        </inertia>
      </inertial>
      <collision name="collision">
        <pose>0.2 0 -0.032 0 0 0</pose>
        <geometry>
          <box>
            <size>0.4 0.1115 0.064</size>
          </box>
        </geometry>
        <surface>
          <friction>
            <ode>
              <mu>1000000</mu>
              <mu2>1000000</mu2>
            </ode>
          </friction>
          <contact>
            <ode>
              <min_depth>0.01</min_depth>
              <max_vel>0</max_vel>
            </ode>
          </contact>
        </surface>
      </collision>
      <visual name="visual">
        <pose>0.2 0 -0.032 0 0 0</pose>
        <geometry>
          <box>
            <size>0.4 0.1115 0.064</size>
          </box>
        </geometry>
        <material>
          <ambient>0.1 0.1 0.3 1</ambient>
          <diffuse>0.2 0.2 0.2 1</diffuse>
          <specular>0 0 0 1</specular>
          <emissive>0 0 0 1</emissive>
        </material>
      </visual>
    </link>
  </gazebo>
  <gazebo>
    <joint name="track_left_straight_segment_joint0" type="prismatic">
      <child>track_left_straight_segment_link0</child>
      <parent>base_link</parent>
      <axis>
        <xyz>1 0 0</xyz>
        <use_parent_model_frame>0</use_parent_model_frame>
      </axis>
      <physics>
        <ode>
          <implicit_spring_damper>1</implicit_spring_damper>
        </ode>
      </physics>
    </joint>
  </gazebo>
  <gazebo>
    <joint name="track_left_straight_segment_joint1" type="prismatic">
      <child>track_left_straight_segment_link1</child>
      <parent>base_link</parent>
      <axis>
        <xyz>1 0 0</xyz>
        <use_parent_model_frame>0</use_parent_model_frame>
      </axis>
      <physics>
        <ode>
          <implicit_spring_damper>1</implicit_spring_damper>
        </ode>
      </physics>
    </joint>
  </gazebo>
  <gazebo>
    <link name="track_left_arc_segment_link0">
      <pose>0.2 0.095 0.064 0 0.0 0</pose>
      <inertial>
        <pose>0 0 -0.064 1.5707963267948966 0 0</pose>
        <mass>0.1</mass>
        <inertia>
          <ixx>0.00020600208333333334</ixx>
          <ixy>0</ixy>
          <ixz>0</ixz>
          <iyy>0.00020600208333333334</iyy>
          <iyz>0</iyz>
          <izz>0.00020480000000000002</izz>
        </inertia>
      </inertial>
      <collision name="collision">
        <pose>0 0 -0.064 1.5707963267948966 0 0</pose>
        <geometry>
          <cylinder>
            <length>0.1115</length>
            <radius>0.064</radius>
          </cylinder>
        </geometry>
        <surface>
          <friction>
            <ode>
              <mu>1000000</mu>
              <mu2>100000</mu2>
            </ode>
          </friction>
          <contact>
            <ode>
              <min_depth>0.01</min_depth>
              <max_vel>0</max_vel>
            </ode>
          </contact>
        </surface>
      </collision>
      <visual name="visual">
        <pose>0 0 -0.064 1.5707963267948966 0 0</pose>
        <geometry>
          <cylinder>
            <length>0.1115</length>
            <radius>0.064</radius>
          </cylinder>
        </geometry>
        <material>
          <ambient>0.1 0.1 0.3 1</ambient>
          <diffuse>0.2 0.2 0.2 1</diffuse>
          <specular>0 0 0 1</specular>
          <emissive>0 0 0 1</emissive>
        </material>
      </visual>
    </link>
  </gazebo>
  <gazebo>
    <link name="track_left_arc_segment_link1">
      <pose>-0.2 0.095 -0.064 0 3.141592653589793 0</pose>
      <inertial>
        <pose>0 0 -0.064 1.5707963267948966 0 0</pose>
        <mass>0.1</mass>
        <inertia>
          <ixx>0.00020600208333333334</ixx>
          <ixy>0</ixy>
          <ixz>0</ixz>
          <iyy>0.00020600208333333334</iyy>
          <iyz>0</iyz>
          <izz>0.00020480000000000002</izz>
        </inertia>
      </inertial>
      <collision name="collision">
        <pose>0 0 -0.064 1.5707963267948966 0 0</pose>
        <geometry>
          <cylinder>
            <length>0.1115</length>
            <radius>0.064</radius>
          </cylinder>
        </geometry>
        <surface>
          <friction>
            <ode>
              <mu>1000000</mu>
              <mu2>100000</mu2>
            </ode>
          </friction>
          <contact>
            <ode>
              <min_depth>0.01</min_depth>
              <max_vel>0</max_vel>
            </ode>
          </contact>
        </surface>
      </collision>
      <visual name="visual">
        <pose>0 0 -0.064 1.5707963267948966 0 0</pose>
        <geometry>
          <cylinder>
            <length>0.1115</length>
            <radius>0.064</radius>
          </cylinder>
        </geometry>
        <material>
          <ambient>0.1 0.1 0.3 1</ambient>
          <diffuse>0.2 0.2 0.2 1</diffuse>
          <specular>0 0 0 1</specular>
          <emissive>0 0 0 1</emissive>
        </material>
      </visual>
    </link>
  </gazebo>
  <gazebo>
    <joint name="track_left_arc_segment_joint0" type="revolute">
      <child>track_left_arc_segment_link0</child>
      <parent>base_link</parent>
      <pose>0 0 -0.064 0 0 0</pose>
      <axis>
        <xyz>0 1 0</xyz>
        <use_parent_model_frame>0</use_parent_model_frame>
      </axis>
      <physics>
        <ode>
          <implicit_spring_damper>1</implicit_spring_damper>
        </ode>
      </physics>
    </joint>
  </gazebo>
  <gazebo>
    <joint name="track_left_arc_segment_joint1" type="revolute">
      <child>track_left_arc_segment_link1</child>
      <parent>base_link</parent>
      <pose>0 0 -0.064 0 0 0</pose>
      <axis>
        <xyz>0 1 0</xyz>
        <use_parent_model_frame>0</use_parent_model_frame>
      </axis>
      <physics>
        <ode>
          <implicit_spring_damper>1</implicit_spring_damper>
        </ode>
      </physics>
    </joint>
  </gazebo>
  <gazebo>
    <plugin filename="libContinuousTrack.so" name="track_left">
      <sprocket>
        <joint>sprocket_left_axle</joint>
        <pitch_diameter>0.223</pitch_diameter>
      </sprocket>
      <trajectory>
        <segment>
          <joint>track_left_straight_segment_joint0</joint>
          <end_position>0.4</end_position>
        </segment>
        <segment>
          <joint>track_left_arc_segment_joint0</joint>
          <end_position>3.141592653589793</end_position>
        </segment>
        <segment>
          <joint>track_left_straight_segment_joint1</joint>
          <end_position>0.4</end_position>
        </segment>
        <segment>
          <joint>track_left_arc_segment_joint1</joint>
          <end_position>3.141592653589793</end_position>
        </segment>
      </trajectory>
      <pattern>
        <elements_per_round>40</elements_per_round>
        <element>
          <collision name="collision">
            <pose>0 0 0.01 1.5707963267948966 0 0</pose>
            <geometry>
              <cylinder>
                <length>0.1115</length>
                <radius>0.0125</radius>
              </cylinder>
            </geometry>
            <surface>
              <friction>
                <ode>
                  <mu>100000</mu>
                  <mu2>100000</mu2>
                </ode>
              </friction>
              <contact>
                <ode>
                  <min_depth>0.01</min_depth>
                  <max_vel>0</max_vel>
                </ode>
              </contact>
            </surface>
          </collision>
          <visual name="visual">
            <pose>0 0 0.01 1.5707963267948966 0 0</pose>
            <geometry>
              <cylinder>
                <length>0.1115</length>
                <radius>0.0125</radius>
              </cylinder>
            </geometry>
            <material>
              <ambient>0.1 0.1 0.3 1</ambient>
              <diffuse>0.2 0.2 0.2 1</diffuse>
              <specular>0 0 0 1</specular>
              <emissive>0 0 0 1</emissive>
            </material>
          </visual>
        </element>
      </pattern>
    </plugin>
  </gazebo>
  <gazebo>
    <link name="track_right_straight_segment_link0">
      <pose>-0.2 -0.095 0.064 0 0.0 0</pose>
      <inertial>
        <pose>0.2 0 -0.032 0 0 0</pose>
        <mass>0.1</mass>
        <inertia>
          <ixx>0.00013773541666666669</ixx>
          <ixy>0</ixy>
          <ixz>0</ixz>
          <iyy>0.0013674666666666669</iyy>
          <iyz>0</iyz>
          <izz>0.001436935416666667</izz>
        </inertia>
      </inertial>
      <collision name="collision">
        <pose>0.2 0 -0.032 0 0 0</pose>
        <geometry>
          <box>
            <size>0.4 0.1115 0.064</size>
          </box>
        </geometry>
        <surface>
          <friction>
            <ode>
              <mu>1000000</mu>
              <mu2>1000000</mu2>
            </ode>
          </friction>
          <contact>
            <ode>
              <min_depth>0.01</min_depth>
              <max_vel>0</max_vel>
            </ode>
          </contact>
        </surface>
      </collision>
      <visual name="visual">
        <pose>0.2 0 -0.032 0 0 0</pose>
        <geometry>
          <box>
            <size>0.4 0.1115 0.064</size>
          </box>
        </geometry>
        <material>
          <ambient>0.1 0.1 0.3 1</ambient>
          <diffuse>0.2 0.2 0.2 1</diffuse>
          <specular>0 0 0 1</specular>
          <emissive>0 0 0 1</emissive>
        </material>
      </visual>
    </link>
  </gazebo>
  <gazebo>
    <link name="track_right_straight_segment_link1">
      <pose>0.2 -0.095 -0.064 0 3.141592653589793 0</pose>
      <inertial>
        <pose>0.2 0 -0.032 0 0 0</pose>
        <mass>0.1</mass>
        <inertia>
          <ixx>0.00013773541666666669</ixx>
          <ixy>0</ixy>
          <ixz>0</ixz>
          <iyy>0.0013674666666666669</iyy>
          <iyz>0</iyz>
          <izz>0.001436935416666667</izz>
        </inertia>
      </inertial>
      <collision name="collision">
        <pose>0.2 0 -0.032 0 0 0</pose>
        <geometry>
          <box>
            <size>0.4 0.1115 0.064</size>
          </box>
        </geometry>
        <surface>
          <friction>
            <ode>
              <mu>1000000</mu>
              <mu2>1000000</mu2>
            </ode>
          </friction>
          <contact>
            <ode>
              <min_depth>0.01</min_depth>
              <max_vel>0</max_vel>
            </ode>
          </contact>
        </surface>
      </collision>
      <visual name="visual">
        <pose>0.2 0 -0.032 0 0 0</pose>
        <geometry>
          <box>
            <size>0.4 0.1115 0.064</size>
          </box>
        </geometry>
        <material>
          <ambient>0.1 0.1 0.3 1</ambient>
          <diffuse>0.2 0.2 0.2 1</diffuse>
          <specular>0 0 0 1</specular>
          <emissive>0 0 0 1</emissive>
        </material>
      </visual>
    </link>
  </gazebo>
  <gazebo>
    <joint name="track_right_straight_segment_joint0" type="prismatic">
      <child>track_right_straight_segment_link0</child>
      <parent>base_link</parent>
      <axis>
        <xyz>1 0 0</xyz>
        <use_parent_model_frame>0</use_parent_model_frame>
      </axis>
      <physics>
        <ode>
          <implicit_spring_damper>1</implicit_spring_damper>
        </ode>
      </physics>
    </joint>
  </gazebo>
  <gazebo>
    <joint name="track_right_straight_segment_joint1" type="prismatic">
      <child>track_right_straight_segment_link1</child>
      <parent>base_link</parent>
      <axis>
        <xyz>1 0 0</xyz>
        <use_parent_model_frame>0</use_parent_model_frame>
      </axis>
      <physics>
        <ode>
          <implicit_spring_damper>1</implicit_spring_damper>
        </ode>
      </physics>
    </joint>
  </gazebo>
  <gazebo>
    <link name="track_right_arc_segment_link0">
      <pose>0.2 -0.095 0.064 0 0.0 0</pose>
      <inertial>
        <pose>0 0 -0.064 1.5707963267948966 0 0</pose>
        <mass>0.1</mass>
        <inertia>
          <ixx>0.00020600208333333334</ixx>
          <ixy>0</ixy>
          <ixz>0</ixz>
          <iyy>0.00020600208333333334</iyy>
          <iyz>0</iyz>
          <izz>0.00020480000000000002</izz>
        </inertia>
      </inertial>
      <collision name="collision">
        <pose>0 0 -0.064 1.5707963267948966 0 0</pose>
        <geometry>
          <cylinder>
            <length>0.1115</length>
            <radius>0.064</radius>
          </cylinder>
        </geometry>
        <surface>
          <friction>
            <ode>
              <mu>1000000</mu>
              <mu2>100000</mu2>
            </ode>
          </friction>
          <contact>
            <ode>
              <min_depth>0.01</min_depth>
              <max_vel>0</max_vel>
            </ode>
          </contact>
        </surface>
      </collision>
      <visual name="visual">
        <pose>0 0 -0.064 1.5707963267948966 0 0</pose>
        <geometry>
          <cylinder>
            <length>0.1115</length>
            <radius>0.064</radius>
          </cylinder>
        </geometry>
        <material>
          <ambient>0.1 0.1 0.3 1</ambient>
          <diffuse>0.2 0.2 0.2 1</diffuse>
          <specular>0 0 0 1</specular>
          <emissive>0 0 0 1</emissive>
        </material>
      </visual>
    </link>
  </gazebo>
  <gazebo>
    <link name="track_right_arc_segment_link1">
      <pose>-0.2 -0.095 -0.064 0 3.141592653589793 0</pose>
      <inertial>
        <pose>0 0 -0.064 1.5707963267948966 0 0</pose>
        <mass>0.1</mass>
        <inertia>
          <ixx>0.00020600208333333334</ixx>
          <ixy>0</ixy>
          <ixz>0</ixz>
          <iyy>0.00020600208333333334</iyy>
          <iyz>0</iyz>
          <izz>0.00020480000000000002</izz>
        </inertia>
      </inertial>
      <collision name="collision">
        <pose>0 0 -0.064 1.5707963267948966 0 0</pose>
        <geometry>
          <cylinder>
            <length>0.1115</length>
            <radius>0.064</radius>
          </cylinder>
        </geometry>
        <surface>
          <friction>
            <ode>
              <mu>1000000</mu>
              <mu2>100000</mu2>
            </ode>
          </friction>
          <contact>
            <ode>
              <min_depth>0.01</min_depth>
              <max_vel>0</max_vel>
            </ode>
          </contact>
        </surface>
      </collision>
      <visual name="visual">
        <pose>0 0 -0.064 1.5707963267948966 0 0</pose>
        <geometry>
          <cylinder>
            <length>0.1115</length>
            <radius>0.064</radius>
          </cylinder>
        </geometry>
        <material>
          <ambient>0.1 0.1 0.3 1</ambient>
          <diffuse>0.2 0.2 0.2 1</diffuse>
          <specular>0 0 0 1</specular>
          <emissive>0 0 0 1</emissive>
        </material>
      </visual>
    </link>
  </gazebo>
  <gazebo>
    <joint name="track_right_arc_segment_joint0" type="revolute">
      <child>track_right_arc_segment_link0</child>
      <parent>base_link</parent>
      <pose>0 0 -0.064 0 0 0</pose>
      <axis>
        <xyz>0 1 0</xyz>
        <use_parent_model_frame>0</use_parent_model_frame>
      </axis>
      <physics>
        <ode>
          <implicit_spring_damper>1</implicit_spring_damper>
        </ode>
      </physics>
    </joint>
  </gazebo>
  <gazebo>
    <joint name="track_right_arc_segment_joint1" type="revolute">
      <child>track_right_arc_segment_link1</child>
      <parent>base_link</parent>
      <pose>0 0 -0.064 0 0 0</pose>
      <axis>
        <xyz>0 1 0</xyz>
        <use_parent_model_frame>0</use_parent_model_frame>
      </axis>
      <physics>
        <ode>
          <implicit_spring_damper>1</implicit_spring_damper>
        </ode>
      </physics>
    </joint>
  </gazebo>
  <gazebo>
    <plugin filename="libContinuousTrack.so" name="track_right">
      <sprocket>
        <joint>sprocket_right_axle</joint>
        <pitch_diameter>0.223</pitch_diameter>
      </sprocket>
      <trajectory>
        <segment>
          <joint>track_right_straight_segment_joint0</joint>
          <end_position>0.4</end_position>
        </segment>
        <segment>
          <joint>track_right_arc_segment_joint0</joint>
          <end_position>3.141592653589793</end_position>
        </segment>
        <segment>
          <joint>track_right_straight_segment_joint1</joint>
          <end_position>0.4</end_position>
        </segment>
        <segment>
          <joint>track_right_arc_segment_joint1</joint>
          <end_position>3.141592653589793</end_position>
        </segment>
      </trajectory>
      <pattern>
        <elements_per_round>40</elements_per_round>
        <element>
          <collision name="collision">
            <pose>0 0 0.01 1.5707963267948966 0 0</pose>
            <geometry>
              <cylinder>
                <length>0.1115</length>
                <radius>0.0125</radius>
              </cylinder>
            </geometry>
            <surface>
              <friction>
                <ode>
                  <mu>100000</mu>
                  <mu2>100000</mu2>
                </ode>
              </friction>
              <contact>
                <ode>
                  <min_depth>0.01</min_depth>
                  <max_vel>0</max_vel>
                </ode>
              </contact>
            </surface>
          </collision>
          <visual name="visual">
            <pose>0 0 0.01 1.5707963267948966 0 0</pose>
            <geometry>
              <cylinder>
                <length>0.1115</length>
                <radius>0.0125</radius>
              </cylinder>
            </geometry>
            <material>
              <ambient>0.1 0.1 0.3 1</ambient>
              <diffuse>0.2 0.2 0.2 1</diffuse>
              <specular>0 0 0 1</specular>
              <emissive>0 0 0 1</emissive>
            </material>
          </visual>
        </element>
      </pattern>
    </plugin>
  </gazebo>
  <!-- ros_control for gazebo -->
  <gazebo>
    <plugin filename="libgazebo_ros_control.so" name="gazebo_ros_control">
      <robotSimType>gazebo_ros_control/DefaultRobotHWSim</robotSimType>
      <legacyModeNS>false</legacyModeNS>
    </plugin>
  </gazebo>
</robot>
